Workbook

Sheet graf 1
M1: MUNDO: PRODUCCIÓN DE CARNE BOVINA Y SUS DERIVADOS, AÑO 2000-2022
M2: (Expresado en
A4: CLASIFIACIONES FAO | B4: 2000 | C4: 2001 | D4: 2002 | E4: 2003 | F4: 2004 | G4: 2005 | H4: 2006 | I4: 2007 | J4: 2008 | K4: 2009 | L4: 2010 | M4: 2011 | N4: 2012 | O4: 2013 | P4: 2014 | Q4: 2015 | R4: 2016 | S4: 2017 | T4: 2018 | U4: 2019 | V4: 2020 | W4: 2021 | X4: 2022 | Y4: 2023
A5: Carne, ganado vacuno, fresca o refrigerada | B5: 55113362 | C5: 54833746 | D5: 55844373 | E5: 56644377 | F5: 58158415 | G5: 58489792 | H5: 59703615 | I5: 61437668 | J5: 61575207 | K5: 61983341 | L5: 61864813 | M5: 61671746 | N5: 62048069 | O5: 63008261 | P5: 63320000 | Q5: 62900673 | R5: 63157550 | S5: 64281534 | T5: 66074787 | U5: 67967153 | V5: 67465425 | W5: 68179140 | X5: 69346116 | Y5: 69462203
A6: Despojos comestibles de bovinos, frescos, refrigerados o congelados | B6: 7337751.6 | C6: 7260718.9 | D6: 7445114.8 | E6: 7582258.5 | F6: 7823906.4 | G6: 7952209 | H6: 8156981.3 | I6: 8384868.1 | J6: 8388696.7 | K6: 8466703.9 | L6: 8463712.6 | M6: 8418858 | N6: 8485583.4 | O6: 8658826.9 | P6: 8710587 | Q6: 8742841.2 | R6: 8698845.6 | S6: 8833308.3 | T6: 9043770.3 | U6: 9381629.1 | V6: 9323204.6 | W6: 9417912.2 | X6: 9570873.6
A7: Grasa bovino, sin procesar | B7: 2824724 | C7: 2791217.4 | D7: 2835436 | E7: 2879338 | F7: 2953632.2 | G7: 2942991.1 | H7: 2986309.9 | I7: 3073497.8 | J7: 3080106 | K7: 3096727.9 | L7: 3060523.3 | M7: 3044771.9 | N7: 3047626.9 | O7: 3084226.8 | P7: 3103698.6 | Q7: 3078046 | R7: 3098907.6 | S7: 3158253.8 | T7: 3248883.4 | U7: 3336330.3 | V7: 3314641.6 | W7: 3340140 | X7: 3392342.9
A8: total | B8: =SUM(B4:B7) -> 65277838 | C8: =SUM(C4:C7) -> 64887683 | D8: =SUM(D4:D7) -> 66126926 | E8: =SUM(E4:E7) -> 67107976 | F8: =SUM(F4:F7) -> 68937958 | G8: =SUM(G4:G7) -> 69386997 | H8: =SUM(H4:H7) -> 70848913 | I8: =SUM(I4:I7) -> 72898041 | ... X8: =SUM(X4:X7) -> 82311355
A37: CLASIFIACIONES FAO | B37: 2000 | C37: 2001 | D37: 2002 | E37: 2003 | F37: 2004 | G37: 2005 | H37: 2006 | I37: 2007 | J37: 2008 | K37: 2009 | L37: 2010 | M37: 2011 | N37: 2012 | O37: 2013 | P37: 2014 | Q37: 2015 | R37: 2016 | S37: 2017 | T37: 2018 | U37: 2019 | V37: 2020 | W37: 2021 | X37: 2022 | Y37: 2023
A38: Carne, ganado vacuno, fresca o refrigerada | B38: 55113362 | C38: 54833746 | D38: 55844373 | E38: 56644377 | F38: 58158415 | G38: 58489792 | H38: 59703615 | I38: 61437668 | J38: 61575207 | K38: 61983341 | L38: 61864813 | M38: 61671746 | N38: 62048069 | O38: 63008261 | P38: 63320000 | Q38: 62900673 | R38: 63157550 | S38: 64281534 | T38: 66074787 | U38: 67967153 | V38: 67465425 | W38: 68179140 | X38: 69346116 | Y38: 69462203
A39: Carne, ganado vacuno, fresca o refrigerada | B39: =B38/1000000 -> 55.113362 | C39: =C38/1000000 -> 54.833746 | D39: =D38/1000000 -> 55.844373 | E39: =E38/1000000 -> 56.644377 | F39: =F38/1000000 -> 58.158415 | G39: =G38/1000000 -> 58.489792 | H39: =H38/1000000 -> 59.703615 | I39: =I38/1000000 -> 61.437668 | ... Y39: =Y38/1000000 -> 69.462203
C40: =(C38-B38)/B38 -> -0.0050734735 | D40: =(D38-C38)/C38 -> 0.018430755 | E40: =(E38-D38)/D38 -> 0.014325592 | F40: =(F38-E38)/E38 -> 0.026728835 | G40: =(G38-F38)/F38 -> 0.0056978341 | H40: =(H38-G38)/G38 -> 0.020752736 | I40: =(I38-H38)/H38 -> 0.029044349 | J40: =(J38-I38)/I38 -> 0.0022386799 | ... Y40: =(Y38-X38)/X38 -> 0.0016740175
Y45: =(Y38-B38)/B38 -> 0.26035139
C46: MUNDO: PRODUCCIÓN DE CARNE BOVINA FRESCA O REFRIGERADA, PERÍODO 2000-2023
C47: (Expresado en millones de toneladas)

Sheet Grafico 2
B2: PAÍS | C2: 2014 | D2: 2018 | E2: 2023 | G2: MUNDO: RANKING DE PAÍSES PRODUCTORES DE CARNE BOVINA, EN TONELADAS, AÑOS 2014-2018-2023 | N2: PAÍS | O2: 2023 | P2: 2014 | Q2: 2018
B3: Canadá | C3: 1.068591 | D3: 1.265935 | E3: 1.347831 | N3: Estados Unidos de América | O3: 12285731
B4: Federación de Rusia | C4: 1.654135 | D4: 1.608136 | E4: 1.6596 | N4: Brasil | O4: 11160000
B5: Turquía | C5: 0.81567378 | D5: 1.2812343 | E5: 1.670606 | N5: China | O5: 6788851.1
B6: México | C6: 1.827152 | D6: 1.9808463 | E6: 2.2149277 | N6: China, Continental | O6: 6774120 | P6: 5541480 | Q6: 5796540
B7: Australia | C7: 2.595149 | D7: 2.308547 | E7: 2.236234 | N7: Argentina | O7: 3287045.9
B8: Argentina | C8: 2.674 | D8: 3.066094 | E8: 3.2870459 | N8: Australia | O8: 2236234
B9: China, Continental | C9: 5.54148 | D9: 5.79654 | E9: 6.77412 | N9: México | O9: 2214927.7
B10: China | C10: 5.5562522 | D10: 5.8101618 | E10: 6.7888511 | N10: Turquía | O10: 1670606
B11: Brasil | C11: 9.723 | D11: 9.9 | E11: 11.16 | N11: Federación de Rusia | O11: 1659600
B12: Estados Unidos de América | C12: 11.698116 | D12: 12.255874 | E12: 12.285731 | N12: Canadá | O12: 1347831
N13: Estados Unidos de América | P13: 11698116 | Q13: 12255874
B14: Resto | C14: 25127523 | D14: 26432815 | E14: =E16-SUM(E3:E12) -> 20.037256 | N14: Brasil | P14: 9723000 | Q14: 9900000
N15: China | P15: 5556252.2 | Q15: 5810161.8
B16: Total general | C16: 68876252 | D16: 71884949 | E16: 69.462203 | N16: Argentina | P16: 2674000 | Q16: 3066094
B17: Bolivia | C17: 224651 | D17: 268000 | E17: 0.326596 | N17: Australia | P17: 2595149 | Q17: 2308547
N18: México | P18: 1827152 | Q18: 1980846.3
N19: Federación de Rusia | P19: 1654135 | Q19: 1608136
E20: =E12/E16 -> 0.1768693 | N20: Francia | O20: 1301420 | P20: 1410854 | Q20: 1460000
N21: Canadá | P21: 1068591 | Q21: 1265935
N22: Turquía | P22: 815673.78 | Q22: 1281234.3
B25: PAÍS | C25: 2014 | D25: 2018 | E25: 2023
B26: Estados Unidos de América | C26: 11698116 | D26: 12255874 | E26: 12285731 | G26: =(E11-C11)/C11 -> 0.14779389
B27: Brasil | C27: 9723000 | D27: 9900000 | E27: 11160000
B28: China | C28: 5556252.2 | D28: 5810161.8 | E28: 6788851.1
B29: China, Continental | C29: 5541480 | D29: 5796540 | E29: 6774120
B30: Argentina | C30: 2674000 | D30: 3066094 | E30: 3287045.9
B31: Australia | C31: 2595149 | D31: 2308547 | E31: 2236234
B32: México | C32: 1827152 | D32: 1980846.3 | E32: 2214927.7
B33: Turquía | C33: 815673.78 | D33: 1281234.3 | E33: 1670606
B34: Federación de Rusia | C34: 1654135 | D34: 1608136 | E34: 1659600
B35: Canadá | C35: 1068591 | D35: 1265935 | E35: 1347831
B39: PAÍS | C39: 2018 | D39: 2022 | E39: PROM
B40: Estados Unidos de América | C40: =(D26-C26)/C26 -> 0.047679302 | D40: =(E26-D26)/D26 -> 0.002436138 | E40: =AVERAGE(C40:D40) -> 0.02505772
B41: Brasil | C41: =(D27-C27)/C27 -> 0.018204258 | D41: =(E27-D27)/D27 -> 0.12727273 | E41: =AVERAGE(C41:D41) -> 0.072738493
B42: China | C42: =(D28-C28)/C28 -> 0.045697998 | D42: =(E28-D28)/D28 -> 0.16844442 | E42: =AVERAGE(C42:D42) -> 0.10707121
B43: Argentina | C43: =(D29-C29)/C29 -> 0.046027415 | D43: =(E29-D29)/D29 -> 0.16864888 | E43: =AVERAGE(C43:D43) -> 0.10733815
B44: Australia | C44: =(D30-C30)/C30 -> 0.14663201 | D44: =(E30-D30)/D30 -> 0.072062977 | E44: =AVERAGE(C44:D44) -> 0.10934749
B45: México | C45: =(D31-C31)/C31 -> -0.11043759 | D45: =(E31-D31)/D31 -> -0.031324032 | E45: =AVERAGE(C45:D45) -> -0.070880811
B46: Federación de Rusia | C46: =(D32-C32)/C32 -> 0.084116888 | D46: =(E32-D32)/D32 -> 0.1181724 | E46: =AVERAGE(C46:D46) -> 0.10114464
...

Sheet graf 3 
A1: Exporters | B1: 2016 | C1: 2017 | D1: 2018 | E1: 2019 | F1: 2020 | G1: 2021 | H1: 2022 | I1: 2023 | J1: Nov 2024 | M1: 2016 | N1: 2017 | O1: 2018 | P1: 2019 | Q1: 2020 | R1: 2021 | S1: 2022 | T1: 2023 | U1: 2024
A2: United States of America | B2: 355379 | C2: 439456 | D2: 454386 | E2: 428629 | F2: 428887 | G2: 477903 | H2: 425724 | I2: 406000 | J2: 356919.81 | L2: Cantidad | M2: 3808233 | N2: 3883699 | O2: 4037992 | P2: 3829973 | Q2: 3690951 | R2: 3591175 | S2: 3422441 | T2: 3756598 | U2: =U11/1000 -> 3181228.6
A3: Canada | B3: 247026 | C3: 258783 | D3: 280787 | E3: 308073 | F3: 296560 | G3: 332908 | H3: 335926 | I3: 357002 | J3: 320323.3 | M3: =(S2-M2)/M2 -> -0.10130473 | N3: =(N2-M2)/M2 -> 0.01981654 | O3: =(O2-N2)/N2 -> 0.039728362 | P3: =(P2-O2)/O2 -> -0.051515456 | Q3: =(Q2-P2)/P2 -> -0.036298428 | R3: =(R2-Q2)/Q2 -> -0.027032599 | S3: =(S2-R2)/R2 -> -0.046985736 | T3: =(T2-S2)/S2 -> 0.097637037
A4: Australia | B4: 281587 | C4: 280864 | D4: 305395 | E4: 313639 | F4: 306920 | G4: 278993 | H4: 229914 | I4: 279197 | J4: 313689.12
A5: Netherlands | B5: 396856 | C5: 394039 | D5: 401185 | E5: 405021 | F5: 374301 | G5: 381173 | H5: 376657 | I5: 374249 | J5: 307473.76 | M5: Mundo: Exportaciones de Carne bovina fresca o refrigerada, año 2016-2024
A6: Brazil | B6: 137650 | C6: 125088 | D6: 190132 | E6: 196393 | F6: 165902 | G6: 177686 | H6: 142072 | I6: 172799 | J6: 263844.82 | S6: 21218
A7: Poland | B7: 278610 | C7: 294702 | D7: 302048 | E7: 273146 | F7: 270618 | G7: 265526 | H7: 253731 | I7: 294368 | J7: 241461.95 | S7: 29616 | T7: =(S7-S6)/S6 -> 0.39579602
A8: Ireland | B8: 286359 | C8: 300114 | D8: 299559 | E8: 291502 | F8: 282390 | G8: 21880 | H8: 26030 | I8: 261360 | J8: 221375.19
A9: Spain | B9: 131959 | C9: 131717 | D9: 129260 | E9: 148779 | F9: 158187 | G9: 158447 | H9: 175075 | I9: 198386 | J9: 167943.92
A10: France | B10: 186960 | C10: 188069 | D10: 192470 | E10: 184141 | F10: 174430 | G10: 182594 | H10: 180379 | I10: 162166 | J10: 159864.73
A11: Paraguay | B11: 111395 | C11: 115139 | D11: 89929 | E11: 99048 | F11: 114917 | G11: 143750 | H11: 154551 | I11: 144475 | J11: 121925.86 | U11: 3181228589
A12: Argentina | B12: 63054 | C12: 70848 | D12: 87416 | E12: 90270 | F12: 88120 | G12: 93135 | H12: 89038 | I12: 92897 | J12: 95831.933
A13: Belgium | B13: 127480 | C13: 137664 | D13: 137107 | E13: 114203 | F13: 107085 | G13: 115320 | H13: 107637 | I13: 106290 | J13: 89513.789
A14: Italy | B14: 88004 | C14: 81884 | D14: 80099 | E14: 80829 | F14: 77980 | G14: 85688 | H14: 81863 | I14: 77536 | J14: 88542.645
A15: United Kingdom | B15: 82572 | C15: 78594 | D15: 83361 | E15: 99397 | F15: 75729 | G15: 60854 | H15: 83686 | I15: 73433 | J15: 72403.038
A16: Austria | B16: 83029 | C16: 82487 | D16: 80949 | E16: 77308 | F16: 74180 | G16: 76547 | H16: 79966 | I16: 89915 | J16: 61399.315
A17: Pakistan | B17: 38694 | C17: 29112 | D17: 41105 | E17: 54558 | F17: 62732 | G17: 64692 | H17: 71260 | I17: 88023 | J17: 46076.771
A18: Denmark | B18: 64513 | C18: 63402 | D18: 68313 | E18: 59174 | F18: 53674 | G18: 55795 | H18: 54281 | I18: 50690 | J18: 35867.802
A19: Nicaragua | B19: 38145 | C19: 46985 | D19: 47737 | E19: 51328 | F19: 57501 | G19: 64054 | H19: 59831 | I19: 61333 | J19: 33517.767
A20: New Zealand | B20: 29085 | C20: 27553 | D20: 31347 | E20: 37267 | F20: 37535 | G20: 41011 | H20: 38072 | I20: 35683 | J20: 28218.077
A21: South Africa | B21: 21067 | C21: 18074 | D21: 14045 | E21: 12600 | F21: 16587 | G21: 15119 | H21: 15477 | I21: 18340 | J21: 19862.592 | M21: 2016 | N21: 2017 | O21: 2018 | P21: 2019 | Q21: 2020 | R21: 2021 | S21: 2022 | T21: 2023
A22: Lithuania | B22: 21335 | C22: 20953 | D22: 20320 | E22: 20786 | F22: 19146 | G22: 20718 | H22: 21456 | I22: 20409 | J22: 17069.286 | L22: valor exportado de carne fresca | M22: 20,649,966 | N22: 22,010,852 | O22: 23,942,925 | P22: 23,487,847 | Q22: 22,748,008 | R22: 27,739,185 | S22: 28,741,867 | T22: 29,274,735 | U22: 26200319
A23: Kazakhstan | B23: 1573 | C23: 795 | D23: 3659 | E23: 1609 | F23: 7700 | G23: 6341 | H23: 18270 | I23: 15588 | J23: 14676.179
A24: India | B24: 12897 | C24: 12867 | D24: 11907 | E24: 11409 | F24: 8688 | G24: 16873 | H24: 23713 | I24: 30270 | J24: 14592.401
A25: Portugal | B25: 9288 | C25: 9555 | D25: 13731 | E25: 11807 | F25: 12504 | G25: 14539 | H25: 15757 | I25: 15371 | J25: 13231.525
A26: Czech Republic | B26: 10233 | C26: 8877 | D26: 10443 | E26: 11820 | F26: 13134 | G26: 11949 | H26: 13611 | I26: 16389 | J26: 12922.839 | M26: 2016 | N26: 2017 | O26: 2018 | P26: 2019 | Q26: 2020 | R26: 2021 | S26: 2022 | T26: 2023
A27: Uruguay | B27: 42310 | C27: 42702 | D27: 39463 | E27: 36236 | F27: 32740 | G27: 42963 | H27: 39182 | I27: 40451 | J27: 10811.422 | L27: Cantidad | M27: =+M2+'graf 4'!O5 -> 8972099 | N27: =+N2+'graf 4'!P5 -> 9340213 | O27: =+O2+'graf 4'!Q5 -> 9824274 | P27: =+P2+'graf 4'!R5 -> 10240007 | Q27: =+Q2+'graf 4'!S5 -> 9848060 | R27: =+R2+'graf 4'!T5 -> 9820961 | S27: =+S2+'graf 4'!U5 -> 10226487 | T27: =+T2+'graf 4'!V5 -> 10685843
A28: Bulgaria | B28: 594 | C28: 950 | D28: 582 | E28: 104 | F28: 178 | G28: 362 | H28: 313 | I28: 5672 | J28: 9085.387
A29: Latvia | B29: 10456 | C29: 10427 | D29: 10502 | E29: 8584 | F29: 8557 | G29: 10594 | H29: 9200 | I29: 0 | J29: 8984.761
A30: Japan | B30: 1005 | C30: 1336 | D30: 1910 | E30: 2066 | F30: 2341 | G30: 3490 | H30: 3737 | I30: 3475 | J30: 4222.299
A31: Romania | B31: 8386 | C31: 13414 | D31: 9390 | E31: 6118 | F31: 3576 | G31: 4328 | H31: 5702 | I31: 4877 | J31: 4200.191
A32: Croatia | B32: 5839 | C32: 5055 | D32: 6522 | E32: 6494 | F32: 5287 | G32: 5318 | H32: 5919 | I32: 6050 | J32: 4095.835
A33: Finland | B33: 2135 | C33: 2384 | D33: 2793 | E33: 5264 | F33: 5139 | G33: 4217 | H33: 4738 | I33: 5270 | J33: 3889.382
A34: Slovenia | B34: 4811 | C34: 5083 | D34: 5790 | E34: 6834 | F34: 6496 | G34: 7068 | H34: 5969 | I34: 4536 | J34: 2804.869
A35: Hungary | B35: 0 | C35: 0 | D35: 0 | E35: 0 | F35: 0 | G35: 0 | H35: 0 | I35: 0 | J35: 2218.593
A36: Costa Rica | B36: 4832 | C36: 3064 | D36: 2676 | E36: 2170 | F36: 2322 | G36: 2227 | H36: 1505 | I36: 2547 | J36: 2059.829
A37: Estonia | B37: 809 | C37: 661 | D37: 674 | E37: 708 | F37: 1224 | G37: 2011 | H37: 2191 | I37: 2288 | J37: 1870.797
A38: Luxembourg | B38: 2028 | C38: 1848 | D38: 2235 | E38: 2416 | F38: 2225 | G38: 2041 | H38: 1847 | I38: 1746 | J38: 1345.657
A39: Colombia | B39: 3465 | C39: 9221 | D39: 4694 | E39: 4736 | F39: 11257 | G39: 19465 | H39: 11663 | I39: 5852 | J39: 996.162
A40: Serbia | B40: 1701 | C40: 3249 | D40: 6032 | E40: 1947 | F40: 3242 | G40: 1735 | H40: 846 | I40: 821 | J40: 966.877
...

Sheet graf 4
A4: Exportadores | B4: 2016 | C4: 2017 | D4: 2018 | E4: 2019 | F4: 2020 | G4: 2021 | H4: 2022 | I4: 2023 | J4: 2024 | O4: 2016 | P4: 2017 | Q4: 2018 | R4: 2019 | S4: 2020 | T4: 2021 | U4: 2022 | V4: 2023 | W4: 2024
A5: Brasil | B5: 938392 | C5: 1081279 | D5: 1163533 | E5: 1356639 | F5: 1558502 | G5: 1382514 | H5: 1849255 | I5: 1833081 | J5: 2079520 | N5: MUNDO | O5: 5163866 | P5: 5456514 | Q5: 5786282 | R5: 6410034 | S5: 6157109 | T5: 6229786 | U5: 6804046 | V5: 6929245 | W5: 5942349.9
A6: Australia | B6: 778096 | C6: 782225 | D6: 887617 | E6: 1016961 | F6: 833354 | G6: 742344 | H6: 752170 | I6: 944024 | J6: 1020565.6 | O6: =(U5-O5)/O5 -> 0.31762637
A7: Argentina | B7: 91275 | C7: 138434 | D7: 281674 | E7: 472011 | F7: 527858 | G7: 472225 | H7: 533148 | I7: 580513 | J7: 603559.64 | P7: Mundo: Exportación de carne bovina congelada, en toneladas, año 2016 al mes de noviembre de 2024
A8: Estados Unidos de América | B8: 460229 | C8: 478766 | D8: 559432 | E8: 538864 | F8: 512616 | G8: 625014 | H8: 719379 | I8: 567906 | J8: 521590.64
A9: India | B9: 1246721 | C9: 1300395 | D9: 1099118 | E9: 1087313 | F9: 934329 | G9: 1010719 | H9: 1036367 | I9: 1109893 | J9: 491855.78
A10: Nueva Zelandia | B10: 389887 | C10: 394733 | D10: 417656 | E10: 437021 | F10: 448781 | G10: 476569 | H10: 463500 | I10: 493015 | J10: 352049.41 | M10: 6804046 | N10: =M10+M11 -> 10226487
A11: Paraguay | B11: 166224 | C11: 154577 | D11: 170528 | E11: 149851 | F11: 157141 | G11: 175525 | H11: 182797 | I11: 176000 | J11: 190244.88 | M11: 3422441
A12: Irlanda | B12: 78756 | C12: 71029 | D12: 74296 | E12: 96486 | F12: 106080 | G12: 0 | H12: 0 | I12: 119469 | J12: 103067.3
A13: Uruguay | B13: 255943 | C13: 265842 | D13: 292100 | E13: 299306 | F13: 276787 | G13: 373702 | H13: 342229 | I13: 320230 | J13: 76620.034
A14: Polonia | B14: 69277 | C14: 95154 | D14: 88457 | E14: 104640 | F14: 103137 | G14: 106087 | H14: 107982 | I14: 105160 | J14: 73564.815
A15: Canadá | B15: 62167 | C15: 66294 | D15: 70283 | E15: 78178 | F15: 80267 | G15: 105468 | H15: 94105 | I15: 66048 | J15: 61319.047
A16: Países Bajos | B16: 39499 | C16: 47367 | D16: 43833 | E16: 56122 | F16: 47672 | G16: 65081 | H16: 61680 | I16: 50432 | J16: 42350.516
A17: España | B17: 37109 | C17: 40594 | D17: 33557 | E17: 42516 | F17: 41743 | G17: 48664 | H17: 45492 | I17: 42199 | J17: 33799.807
A18: Reino Unido | B18: 27755 | C18: 26912 | D18: 27119 | E18: 0 | F18: 41329 | G18: 42026 | H18: 37216 | I18: 30212 | J18: 31120.259
A19: Bolivia, Estado Plurinacional de | B19: 350 | C19: 277 | D19: 490 | E19: 2415 | F19: 13880 | G19: 16056 | H19: 18625 | I19: 26086 | J19: 27663.903
A20: Italia | B20: 41677 | C20: 48354 | D20: 43468 | E20: 37054 | F20: 34818 | G20: 45781 | H20: 39946 | I20: 37456 | J20: 27439.294
A21: Nicaragua | B21: 55029 | C21: 69790 | D21: 64250 | E21: 66018 | F21: 65540 | G21: 69571 | H21: 57321 | I21: 54333 | J21: 26883.728
A22: Francia | B22: 18900 | C22: 18320 | D22: 17425 | E22: 15197 | F22: 15673 | G22: 24426 | H22: 23537 | I22: 22199 | J22: 25258.259
A23: Costa Rica | B23: 9850 | C23: 12620 | D23: 14217 | E23: 22677 | F23: 26043 | G23: 27599 | H23: 25727 | I23: 24302 | J23: 19614.606
... A43: República Checa | B43: 884 | C43: 1338 | D43: 1499 | E43: 1393 | F43: 922 | G43: 894 | H43: 1114 | I43: 921 | J43: 971.525
A44: Honduras | B44: 374 | C44: 1792 | D44: 2936 | E44: 2994 | F44: 2738 | G44: 2159 | I44: 1530 | J44: 889.05
A45: Kenya | B45: 1392 | C45: 1798 | D45: 1539 | E45: 1184 | F45: 1063 | G45: 1162 | H45: 1509 | I45: 1226 | J45: 726.684
A46: Guatemala | B46: 948 | C46: 1095 | D46: 1410 | E46: 1920 | F46: 1251 | G46: 1396 | H46: 1059 | I46: 1126 | J46: 705.127
A47: Estonia | B47: 622 | C47: 863 | D47: 923 | E47: 546 | F47: 668 | G47: 932 | H47: 600 | I47: 368 | J47: 696.265
A48: Eslovenia | B48: 406 | C48: 388 | D48: 403 | E48: 311 | F48: 345 | G48: 207 | H48: 338 | I48: 163 | J48: 562.145
A49: Suecia | B49: 356 | C49: 383 | D49: 350 | E49: 393 | F49: 0 | G49: 652 | H49: 562 | I49: 726 | J49: 487.301
A50: Serbia | B50: 367 | C50: 331 | D50: 441 | E50: 1839 | F50: 1338 | G50: 2085 | H50: 3171 | I50: 662 | J50: 429.039
A51: Finlandia | B51: 1139 | C51: 512 | D51: 654 | E51: 1196 | F51: 420 | G51: 141 | H51: 248 | I51: 693 | J51: 369.685
A52: Eslovaquia | B52: 55 | C52: 90 | D52: 184 | E52: 66 | F52: 78 | G52: 827 | H52: 578 | I52: 528 | J52: 294.617
A53: China | B53: 4143 | C53: 918 | D53: 429 | E53: 207 | F53: 97 | G53: 14 | H53: 39 | I53: 92 | J53: 256.927
A54: Malasia | B54: 2199 | C54: 2168 | D54: 1429 | E54: 1155 | F54: 735 | G54: 550 | H54: 936 | I54: 479 | J54: 194.874
A55: Luxemburgo | B55: 35 | C55: 142 | D55: 119 | E55: 125 | F55: 197 | G55: 248 | H55: 698 | I55: 575 | J55: 190.929
A56: Kazajstán | B56: 73 | C56: 148 | D56: 1052 | E56: 3962 | F56: 1519 | G56: 1025 | H56: 55 | I56: 180 | J56: 175.037
... A69: Camboya | B69: 68 | C69: 7 | D69: 0 | E69: 0 | F69: 0 | G69: 0 | H69: 0 | I69: 0 | J69: 11.858
A70: Sri Lanka | B70: 64 | C70: 61 | E70: 60 | F70: 28 | G70: 33 | H70: 37 | I70: 31 | J70: 11.65
A71: Senegal | B71: 22 | C71: 109 | D71: 394 | E71: 327 | F71: 11 | G71: 7 | H71: 10 | I71: 24 | J71: 10.631
A72: Corea, República de | B72: 3466 | C72: 179 | D72: 175 | E72: 54 | F72: 12 | G72: 11 | H72: 125 | I72: 16 | J72: 8.088
A73: Mozambique | B73: 0 | C73: 0 | D73: 0 | E73: 4 | F73: 2 | G73: 3 | H73: 3 | I73: 1 | J73: 7.02
A74: Singapur | B74: 13636 | C74: 12157 | D74: 11827 | E74: 8071 | F74: 8259 | G74: 7685 | H74: 9783 | I74: 8046 | J74: 6.66
...

Sheet graf 5
B1: Paises expatores de carne bovina.
G2: 0201
C3: 0202 | D3: 0201 | E3: total | G3: United States of America | H3: 425724 | K3: PAÍS | L3: total
B4: Brasil | C4: 1849255 | D4: 142072 | E4: =C4+D4 -> 1991327 | G4: Paises Bajos | H4: 376657 | K4: Brasil | L4: 1991327
B5: India | C5: 1036367 | D5: 23713 | E5: =C5+D5 -> 1060080 | G5: Canada | H5: 335926 | K5: Estados Unidos de América | L5: 1145103
B6: Australia | C6: 752170 | D6: 229914 | E6: =C6+D6 -> 982084 | G6: Australia | H6: 229914 | K6: India | L6: 1060080
B7: Estados Unidos de América | C7: 719379 | D7: 425724 | E7: =C7+D7 -> 1145103 | G7: Poland | H7: 253731 | K7: Australia | L7: 982084
B8: Nueva Zelandia | C8: 463500 | E8: =C8+D8 -> 463500 | G8: Germany | H8: 213051 | K8: Argentina | L8: 622186
B9: Argentina | C9: 533148 | D9: 89038 | E9: =C9+D9 -> 622186 | G9: Ireland | H9: 26030 | K9: Nueva Zelandia | L9: 463500
B10: Uruguay | C10: 342229 | E10: =C10+D10 -> 342229 | G10: France | H10: 180379 | K10: Países Bajos | L10: 438337
B11: Paraguay | C11: 182797 | D11: 154551 | E11: =C11+D11 -> 337348 | G11: Brazil | H11: 142072 | K11: Canadá | L11: 430031
B12: Polonia | C12: 107982 | D12: 253731 | E12: =C12+D12 -> 361713 | G12: Spain | H12: 175075 | K12: Polonia | L12: 361713
B13: Canadá | C13: 94105 | D13: 335926 | E13: =C13+D13 -> 430031 | G13: Paraguay | H13: 154551 | K13: Uruguay | L13: 342229
B14: Irlanda | D14: 26030 | E14: =C14+D14 -> 26030 | G14: Belgium | H14: 107637 | K14: Paraguay | L14: 337348
B15: Belarús | C15: 47518 | E15: =C15+D15 -> 47518 | G15: Argentina | H15: 89038 | K15: Alemania | L15: 259766
B16: Países Bajos | C16: 61680 | D16: 376657 | E16: =C16+D16 -> 438337 | G16: India | H16: 23713 | K16: Belarús | L16: 47518
B17: Hong Kong, China | C17: 45226 | E17: =C17+D17 -> 45226 | G17: Portugal | H17: 15757 | K17: Hong Kong, China | L17: 45226
B18: Alemania | C18: 46715 | D18: 213051 | E18: =C18+D18 -> 259766 | G18: Czech Republic | H18: 13611 | K18: Irlanda | L18: 26030
G19: Sudan | H19: 6068
G20: Colombia | H20: 11663
G21: Latvia | H21: 9200
G22: Ukraine | H22: 34
E26: Gráfico 5 Principales países exportadores de carne bovina, fresca y congelada, año 2022
B27: PAÍS | C27: TOTAL
A28: 1 | B28: Uruguay | C28: 342229
A29: 2 | B29: Polonia | C29: 361713
A30: 3 | B30: Canadá | C30: 430031
A31: 4 | B31: Países Bajos | C31: 438337
A32: 5 | B32: Nueva Zelandia | C32: 463500
A33: 6 | B33: Argentina | C33: 622186
A34: 7 | B34: Australia | C34: 982084
A35: 8 | B35: India | C35: 1060080
A36: 9 | B36: Estados Unidos de América | C36: 1145103
A37: 10 | B37: Brasil | C37: 1991327
B38: TOTAL | C38: =SUM(C28:C37) -> 7836590
B43: 202 | C43: 6929245
B44: 201 | C44: 3422441 | D44: =C43+C44 -> 10351686 | F44: =C37/D44 -> 0.19236741
B47: 2016 | C47: 20054746
B48: 2022 | C48: 38867637 | D48: =(C48-C47)/C48 -> 0.48402456
C51: PAÍS | D51: TOTAL
...

Sheet graf 6
A2: 020110 | B2: Importadores | C2: 2016 | D2: 2017 | E2: 2018 | F2: 2019 | G2: 2020 | H2: 2021 | I2: 2022 | J2: 2023 | M2: Mundo: Importación de carne bovina fresca o refrigerada, en toneladas, año 2016 al mes de noviembre de 2024
B3: Mundo | C3: 509825 | D3: 532030 | E3: 514891 | F3: 508788 | G3: 495875 | H3: 457507 | I3: 480683 | J3: 518516
A4: 020120 | B4: Importadores | F4: 2019 | G4: 2020 | H4: 2021 | I4: 2022 | J4: 2023
B5: Mundo | C5: 870224 | D5: 848957 | E5: 1001377 | F5: 930866 | G5: 851352 | H5: 887342 | I5: 879471 | J5: 841758
A6: 020130 | B6: Importadores | C6: 2016 | D6: 2017 | E6: 2018 | F6: 2019 | G6: 2020 | H6: 2021 | I6: 2022 | J6: 2023
B7: Mundo | C7: 1794148 | D7: 1836201 | E7: 2376108 | F7: 2457203 | G7: 2391690 | H7: 2497877 | I7: 2378565 | J7: 2414507
A9: 0201 | B9: AÑO | C9: 2016 | D9: 2017 | E9: 2018 | F9: 2019 | G9: 2020 | H9: 2021 | I9: 2022 | J9: 2023 | K9: 2024
B10: Mundo | C10: =+C3+C5+C7 -> 3174197 | D10: =+D3+D5+D7 -> 3217188 | E10: =+E3+E5+E7 -> 3892376 | F10: =+F3+F5+F7 -> 3896857 | G10: =+G3+G5+G7 -> 3738917 | H10: =+H3+H5+H7 -> 3842726 | I10: =+I3+I5+I7 -> 3738719 | J10: =+J3+J5+J7 -> 3774781 | K10: 2865395

Sheet graf 7
A1: Exporters | B1: 2016 | C1: 2017 | D1: 2018 | E1: 2019 | F1: 2020 | G1: 2021 | H1: 2022 | I1: 2023 | J1: TOTAL | N1: 2016 | O1: 2017 | P1: 2018 | Q1: 2019 | R1: 2020 | S1: 2021 | T1: 2022
A2: World | B2: 3808233 | C2: 3883699 | D2: 4037992 | E2: 3829973 | F2: 3690951 | G2: 3591175 | H2: 3422441 | I2: 3756598 | J2: =SUM(B2:I2) -> 30021062 | N2: 3808233 | O2: 3883699 | P2: 4037992 | Q2: 3829973 | R2: 3690951 | S2: 3591175 | T2: 3422441
A3: United States of America | B3: 355379 | C3: 439456 | D3: 454386 | E3: 428629 | F3: 428887 | G3: 477903 | H3: 425724 | I3: 406000 | J3: =SUM(B3:I3) -> 3416364 | N3: =(T2-N2)/N2 -> -0.10130473
A4: Netherlands | B4: 396856 | C4: 394039 | D4: 401185 | E4: 405021 | F4: 374301 | G4: 381173 | H4: 376657 | I4: 374249 | J4: =SUM(B4:I4) -> 3103481
A5: Canada | B5: 247026 | C5: 258783 | D5: 280787 | E5: 308073 | F5: 296560 | G5: 332908 | H5: 335926 | I5: 357002 | J5: =SUM(B5:I5) -> 2417065
A6: Australia | B6: 281587 | C6: 280864 | D6: 305395 | E6: 313639 | F6: 306920 | G6: 278993 | H6: 229914 | I6: 279197 | J6: =SUM(B6:I6) -> 2276509 | T6: 21218
A7: Poland | B7: 278610 | C7: 294702 | D7: 302048 | E7: 273146 | F7: 270618 | G7: 265526 | H7: 253731 | I7: 294368 | J7: =SUM(B7:I7) -> 2232749 | T7: 29616 | U7: =(T7-T6)/T6 -> 0.39579602
A8: Germany | B8: 264188 | C8: 241625 | D8: 225407 | E8: 228181 | F8: 201554 | G8: 211139 | H8: 213051 | I8: 209659 | J8: =SUM(B8:I8) -> 1794804
A9: Ireland | B9: 286359 | C9: 300114 | D9: 299559 | E9: 291502 | F9: 282390 | G9: 21880 | H9: 26030 | I9: 261360 | J9: =SUM(B9:I9) -> 1769194
A10: France | B10: 186960 | C10: 188069 | D10: 192470 | E10: 184141 | F10: 174430 | G10: 182594 | H10: 180379 | I10: 162166 | J10: =SUM(B10:I10) -> 1451209
A11: Brazil | B11: 137650 | C11: 125088 | D11: 190132 | E11: 196393 | F11: 165902 | G11: 177686 | H11: 142072 | I11: 172799 | J11: =SUM(B11:I11) -> 1307722
A12: Spain | B12: 131959 | C12: 131717 | D12: 129260 | E12: 148779 | F12: 158187 | G12: 158447 | H12: 175075 | I12: 198386 | J12: =SUM(B12:I12) -> 1231810
A13: Paraguay | B13: 111395 | C13: 115139 | D13: 89929 | E13: 99048 | F13: 114917 | G13: 143750 | H13: 154551 | I13: 144475 | J13: =SUM(B13:I13) -> 973204
A14: Belgium | B14: 127480 | C14: 137664 | D14: 137107 | E14: 114203 | F14: 107085 | G14: 115320 | H14: 107637 | I14: 106290 | J14: =SUM(B14:I14) -> 952786
A15: Argentina | B15: 63054 | C15: 70848 | D15: 87416 | E15: 90270 | F15: 88120 | G15: 93135 | H15: 89038 | I15: 92897 | J15: =SUM(B15:I15) -> 674778
A16: Italy | B16: 88004 | C16: 81884 | D16: 80099 | E16: 80829 | F16: 77980 | G16: 85688 | H16: 81863 | I16: 77536 | J16: =SUM(B16:I16) -> 653883
A17: Austria | B17: 83029 | C17: 82487 | D17: 80949 | E17: 77308 | F17: 74180 | G17: 76547 | H17: 79966 | I17: 89915 | J17: =SUM(B17:I17) -> 644381
A18: United Kingdom | B18: 82572 | C18: 78594 | D18: 83361 | E18: 99397 | F18: 75729 | G18: 60854 | H18: 83686 | I18: 73433 | J18: =SUM(B18:I18) -> 637626
A19: Belarus | B19: 103983 | C19: 98166 | D19: 105692 | E19: 83594 | F19: 84925 | G19: 76664 | H19: 23096 | I19: 4724 | J19: =SUM(B19:I19) -> 580844
A20: Mexico | B20: 156746 | C20: 166646 | D20: 180866 | E20: No Quantity | F20: No Quantity | G20: No Quantity | H20: No Quantity | I20: No Quantity | J20: =SUM(B20:I20) -> 504258
A21: Denmark | B21: 64513 | C21: 63402 | D21: 68313 | E21: 59174 | F21: 53674 | G21: 55795 | H21: 54281 | I21: 50690 | J21: =SUM(B21:I21) -> 469842
A22: Pakistan | B22: 38694 | C22: 29112 | D22: 41105 | E22: 54558 | F22: 62732 | G22: 64692 | H22: 71260 | I22: 88023 | J22: =SUM(B22:I22) -> 450176
A23: Nicaragua | B23: 38145 | C23: 46985 | D23: 47737 | E23: 51328 | F23: 57501 | G23: 64054 | H23: 59831 | I23: 61333 | J23: =SUM(B23:I23) -> 426914
A24: Uruguay | B24: 42310 | C24: 42702 | D24: 39463 | E24: 36236 | F24: 32740 | G24: 42963 | H24: 39182 | I24: 40451 | J24: =SUM(B24:I24) -> 316047
A25: New Zealand | B25: 29085 | C25: 27553 | D25: 31347 | E25: 37267 | F25: 37535 | G25: 41011 | H25: 38072 | I25: 35683 | J25: =SUM(B25:I25) -> 277553
A26: Lithuania | B26: 21335 | C26: 20953 | D26: 20320 | E26: 20786 | F26: 19146 | G26: 20718 | H26: 21456 | I26: 20409 | J26: =SUM(B26:I26) -> 165123
A27: South Africa | B27: 21067 | C27: 18074 | D27: 14045 | E27: 12600 | F27: 16587 | G27: 15119 | H27: 15477 | I27: 18340 | J27: =SUM(B27:I27) -> 131309
A28: India | B28: 12897 | C28: 12867 | D28: 11907 | E28: 11409 | F28: 8688 | G28: 16873 | H28: 23713 | I28: 30270 | J28: =SUM(B28:I28) -> 128624
A29: Portugal | B29: 9288 | C29: 9555 | D29: 13731 | E29: 11807 | F29: 12504 | G29: 14539 | H29: 15757 | I29: 15371 | J29: =SUM(B29:I29) -> 102552
A30: Czech Republic | B30: 10233 | C30: 8877 | D30: 10443 | E30: 11820 | F30: 13134 | G30: 11949 | H30: 13611 | I30: 16389 | J30: =SUM(B30:I30) -> 96456
A31: Sudan | B31: 31860 | C31: 10596 | D31: 8378 | E31: 7137 | F31: 8688 | G31: 10823 | H31: 6068 | I31: 1596 | J31: =SUM(B31:I31) -> 85146
A32: Colombia | B32: 3465 | C32: 9221 | D32: 4694 | E32: 4736 | F32: 11257 | G32: 19465 | H32: 11663 | I32: 5852 | J32: =SUM(B32:I32) -> 70353
... A53: Malaysia | B53: 2469 | C53: 1693 | D53: 554 | E53: 210 | F53: 99 | G53: 623 | H53: 496 | I53: 692 | J53: =SUM(B53:I53) -> 6836
A54: Honduras | B54: 389 | C54: 497 | D54: 937 | E54: 978 | F54: 1344 | G54: 1252 | I54: 410 | J54: =SUM(B54:I54) -> 5807
A55: Greece | B55: 343 | C55: 617 | D55: 354 | E55: 352 | F55: 502 | G55: 534 | H55: 638 | I55: 904 | J55: =SUM(B55:I55) -> 4244
A56: Bolivia, Plurinational State of | B56: 729 | C56: 620 | D56: 770 | E56: 494 | F56: 685 | G56: 642 | H56: 69 | I56: 125 | J56: =SUM(B56:I56) -> 4134
A57: Hong Kong, China | B57: 401 | C57: 472 | D57: 599 | E57: 534 | F57: 301 | G57: 271 | H57: 206 | I57: 319 | J57: =SUM(B57:I57) -> 3103
A58: Chile | B58: 384 | C58: 286 | D58: 336 | E58: 365 | F58: 275 | G58: 318 | H58: 272 | I58: 407 | J58: =SUM(B58:I58) -> 2643
A59: Egypt | B59: 414 | C59: 979 | D59: 392 | E59: 212 | F59: 237 | G59: 90 | H59: 85 | I59: 95 | J59: =SUM(B59:I59) -> 2504
A60: Tanzania, United Republic of | B60: 56 | C60: 820 | D60: 0 | E60: 29 | F60: 89 | G60: 747 | H60: 389 | I60: 261 | J60: =SUM(B60:I60) -> 2391
...

Sheet Graf 7 (2)
C1: 2016 | D1: 2017 | E1: 2018 | F1: 2019 | G1: 2020 | H1: 2021 | I1: 2022 | J1: 2023 | K1: 2024
C2: 3872847 | D2: 4128574 | E2: 5084004 | F2: 5829630 | G2: 5847389 | H2: 6272056 | I2: 6738776 | J2: 6914563 | K2: 5216911.1
D5: Mundo: Importación de carne bovina congelada, en toneladas, año 2016-2023 | K5: =F2+'graf 6'!F10 -> 9726487 | L5: =G2+'graf 6'!G10 -> 9586306
L10: =(J2-C2)/C2 -> 0.78539534
C23: 2016 | D23: 2017 | E23: 2018 | F23: 2019 | G23: 2020 | H23: 2021 | I23: 2022 | J23: 2023 | K23: 2024
C24: =+C2+'graf 6'!C10 -> 7047044 | D24: =+D2+'graf 6'!D10 -> 7345762 | E24: =+E2+'graf 6'!E10 -> 8976380 | F24: =+F2+'graf 6'!F10 -> 9726487 | G24: =+G2+'graf 6'!G10 -> 9586306 | H24: =+H2+'graf 6'!H10 -> 10114782 | I24: =+I2+'graf 6'!I10 -> 10477495 | J24: =+J2+'graf 6'!J10 -> 10689344 | K24: =+K2+'graf 6'!K10 -> 8082306.1
D25: =(D24-C24)/C24 -> 0.042389121 | E25: =(E24-D24)/D24 -> 0.22198078 | F25: =(F24-E24)/E24 -> 0.083564533 | G25: =(G24-F24)/F24 -> -0.014412295 | H25: =(H24-G24)/G24 -> 0.055128221 | I25: =(I24-H24)/H24 -> 0.035859695 | J25: =(J24-I24)/I24 -> 0.020219432 | K25: =(K24-J24)/J24 -> -0.24389129 | L25: =AVERAGE(D25:K25) -> 0.025104775

Sheet graf 8
G1: Top 10 principales países importadores de carne bovina, fresca y congelada, en toneladas, año 2023
B2: Indonesia | C2: 238433580 | D2: =C2/1000 -> 238433.58 | E2: =D2/$D$15 -> 0.022305726
B3: Chile | C3: 2.6445168e+08 | D3: =C3/1000 -> 264451.68 | E3: =D3/$D$15 -> 0.024739748
B4: Francia | C4: 270298917 | D4: =C4/1000 -> 270298.92 | E4: =D4/$D$15 -> 0.025286764
B5: Alemania | C5: 2.9713319e+08 | D5: =C5/1000 -> 297133.19 | E5: =D5/$D$15 -> 0.02779714
B6: Países Bajos | C6: 3.4046425e+08 | D6: =C6/1000 -> 340464.25 | E6: =D6/$D$15 -> 0.031850809
B7: Italia | C7: 374513751 | D7: =C7/1000 -> 374513.75 | E7: =D7/$D$15 -> 0.035036177
B8: República de Corea | C8: 472888201 | D8: =C8/1000 -> 472888.2 | E8: =D8/$D$15 -> 0.044239216
B9: Japón | C9: 503939087 | D9: =C9/1000 -> 503939.09 | E9: =D9/$D$15 -> 0.047144061
B10: Estados Unidos | C10: 1198409747 | D10: =C10/1000 -> 1198409.7 | E10: =D10/$D$15 -> 0.11211256
B11: China | C11: 2736899899 | D11: =C11/1000 -> 2736899.9 | E11: =D11/$D$15 -> 0.25604002
C15: Total producción: | D15: ='Graf 7 (2)'!J2+'graf 6'!J10 -> 10689344

Sheet Graf 9 precio
C1: 2016 | O1: 2017 | AA1: 2018 | AM1: 2019 | AY1: 2020 | BK1: 2021 | BW1: 2022 | CI1: 2023 | CU1: 2024
C2: 3.6332138 | D2: 3.8630454 | E2: 4.0334625 | F2: 3.9631351 | G2: 4.0418401 | H2: 4.1051127 | I2: 4.2554678 | J2: 4.2394843 | K2: 4.1178995 | L2: 4.036549 | M2: 4.2984578 | N2: 4.1430321 | O2: 4.0749094 | P2: 4.2262565 | Q2: 4.3461879 | R2: 4.4103423 | S2: 4.6041284 | T2: 4.6783139 | U2: 4.6660782 | V2: 4.4739456 | W2: 4.3012136 | X2: 4.2509483 | Y2: 4.3314169 | Z2: 4.2833562 | AA2: 4.2960328 | AB2: 4.3535733 | AC2: 4.4394433 | AD2: 4.3782651 | AE2: 4.3200631 | AF2: 4.2438935 | AG2: 4.1882268 | AH2: 4.1144823 | AI2: 4.010314 | AJ2: 3.8643682 | AK2: 3.9464903 | AL2: 4.1853608 | AM2: 4.2413582 | AN2: 4.2791674 | AO2: 4.4764809 | AP2: 4.6989271 | AQ2: 4.600601 | AR2: 4.6291508 | AS2: 4.629702 | AT2: 4.5958611 | AU2: 4.654504 | AV2: 4.8583211 | AW2: 5.93627 | AX2: 5.563579 | AY2: 5.0390999 | AZ2: 4.7173356 | BA2: 4.4736149 | BB2: 4.4452855 | BC2: 5.0810979 | BD2: 5.0981837 | BE2: 4.6988168 | BF2: 4.6323475 | BG2: 4.5990578 | BH2: 4.4247826 | BI2: 4.395902 | BJ2: 4.4021852 | BK2: 4.4566393 | BL2: 4.661669 | BM2: 4.7190993 | BN2: 5.1724794 | BO2: 5.4839923 | BP2: 5.6774477 | BQ2: 5.5856252 | BR2: 5.6096556 | BS2: 5.7678371 | BT2: 5.5335962 | BU2: 5.6934312 | BV2: 5.7474443 | BW2: 5.8064179 | BX2: 5.9938106 | BY2: 6.0682165 | BZ2: 5.9745202 | CA2: 5.9414509 | CB2: 5.8119295 | CC2: 5.7342166 | CD2: 5.5666655 | CE2: 5.4432068 | CF2: 5.3324246 | CG2: 5.0733818 | CH2: 4.7134776 | CI2: 4.6517482 | CJ2: 4.6517482 | CK2: 4.8363851 | CL2: 5.3043157 | CM2: 5.3103784 | CN2: 5.0133059 | CO2: 4.7840254 | CP2: 4.7261541 | CQ2: 4.9030749 | CR2: 4.9796854 | CS2: 4.8832333 | CT2: 4.7913741 | CU2: 4.996384 | CV2: 5.375565 | CW2: 5.729792 | CX2: 6.05028 | CY2: 5.8763093 | CZ2: 5.8516948 | DA2: 6.1882875 | DB2: 6.3351728 | DC2: 6.2960425 | DD2: 6.059766 | DE2: 6.183042 | DF2: 6.2332505

Sheet Gráf 10
A1: Bolivia; producción de Carne en kilogramos, año 2015-2023
A3: 2015 | B3: 1.7924377e+08 | E3: 2015 | F3: =B3/1000000 -> 179.24377
A4: 2016 | B4: 1.9709071e+08 | E4: 2016 | F4: =B4/1000000 -> 197.09071
A5: 2017 | B5: 2.014154e+08 | E5: 2017 | F5: =B5/1000000 -> 201.4154
A6: 2018 | B6: 2.1887069e+08 | E6: 2018 | F6: =B6/1000000 -> 218.87069
A7: 2019 | B7: 2.0420321e+08 | E7: 2019 | F7: =B7/1000000 -> 204.20321
A8: 2020 | B8: 1.931723e+08 | E8: 2020 | F8: =B8/1000000 -> 193.1723
A9: 2021 | B9: 2.1344697e+08 | E9: 2021 | F9: =B9/1000000 -> 213.44697
A10: 2022 (p) | B10: 2.3009038e+08 | E10: 2022 (p) | F10: =B10/1000000 -> 230.09038
A11: 2023 (p) | B11: 2.5059158e+08 | E11: 2023 (p) | F11: =B11/1000000 -> 250.59158 | G11: g
A12: 2024 (p) | B12: 2.5292811e+08 | E12: 2024 (p) | F12: =B12/1000000 -> 252.92811
A16: 2015
A17: 2016 | B17: =(B4-B3)/B3 -> 0.099567953 | C17: =B17*B3 -> 17846936
A18: 2017 | B18: =(B5-B4)/B4 -> 0.02194266 | C18: =B18*B4 -> 4324694.3
A19: 2018 | B19: =(B6-B5)/B5 -> 0.086663109 | C19: =B19*B5 -> 17455285 | G19: =B11-B4 -> 53500870
A20: 2019 | B20: =(B7-B6)/B6 -> -0.067014344 | C20: =B20*B6 -> -14667475
A21: 2020 | B21: =(B8-B7)/B7 -> -0.054019298 | C21: =B21*B7 -> -11030914
A22: 2021 (p) | B22: =(B9-B8)/B8 -> 0.10495642 | C22: =B22*B8 -> 20274673
A23: 2022 (p) | B23: =(B10-B9)/B9 -> 0.077974425 | C23: =B23*B9 -> 16643405 | D23: =(B12-B8)/B8*100 -> 30.933946
A24: 2023 (p) | B24: =(B11-B10)/B10 -> 0.089100652 | C24: =B24*B10 -> 20501203
B25: =AVERAGE(B17:B24) -> 0.044896447

Sheet Grafi 11
A3: Suma de Valor | B3: Año
A4: Área | B4: 2014 | C4: 2018 | D4: 2023 | E4: Total general | G4: PAÍS | H4: 2014 | I4: 2018 | J4: 2023
A5: Argentina | B5: 2210 | C5: 2279 | D5: 2264 | E5: 6753 | G5: Argentina | H5: 221 | I5: 227.9 | J5: 226.4
A6: Bolivia (Estado Plurinacional de) | B6: 1947 | C6: 1948 | D6: 2008 | E6: 5903 | G6: Bolivia | H6: 194.7 | I6: 194.8 | J6: 200.8
A7: Brasil | B7: 2408 | C7: 2500 | D7: 2450 | E7: 7358 | G7: Brasil | H7: 240.8 | I7: 250 | J7: 245
A8: Paraguay | B8: 2340 | C8: 2343 | D8: 2274 | E8: 6957 | G8: Paraguay | H8: 234 | I8: 234.3 | J8: 227.4
A9: Perú | B9: 1426 | C9: 1407 | D9: 1478 | E9: 4311 | G9: Perú | H9: 142.6 | I9: 140.7 | J9: 147.8
A10: Total general | B10: 10331 | C10: 10477 | D10: 10474 | E10: 31282
G11: Rendimiento del ganado bovino kg/carcasa, en Sud América, año 2014-2018-2023
A15: Argentina | B15: 2210 | C15: 2279 | D15: 2264
A16: Bolivia (Estado Plurinacional de) | B16: 1947 | C16: 1948 | D16: 2008
A17: Brasil | B17: 2408 | C17: 2500 | D17: 2450
A18: Paraguay | B18: 2340 | C18: 2343 | D18: 2274
A19: Perú | B19: 1426 | C19: 1407 | D19: 1478

Sheet graf 12 nn
A2: AÑO | B2: T O T A L
A3: 2016 | B3: 9119344 | C3: 3097363 | D3: 6021981 | E3: =B10-B3 -> 1980132.4
A4: 2017 | B4: 9304572 | C4: 3193636 | D4: 6110936
A5: 2018 | B5: 9556195.5 | C5: 3055342.6 | D5: 6500852.9
A6: 2019 | B6: 9741474.7 | C6: 3180354.7 | D6: 6561120
A7: 2020(p) | B7: 10103767 | C7: 3296529.7 | D7: 6807237.2
A8: 2021(p) | B8: 10385482 | C8: 3389856.4 | D8: 6995625.5
A9: 2022(p) | B9: 10739448 | C9: 3527167.9 | D9: 7212280.5
A10: 2023(p) | B10: 11099476 | C10: 3684565.6 | D10: 7414910.8
A11: 2016 | C11: =C3/$B3 -> 0.33964757 | D11: =D3/$B3 -> 0.66035243
A12: 2017 | C12: =C4/$B4 -> 0.34323298 | D12: =D4/$B4 -> 0.65676702
A13: 2018 | C13: =C5/$B5 -> 0.31972374 | D13: =D5/$B5 -> 0.68027626
A14: 2019 | C14: =C6/$B6 -> 0.3264757 | D14: =D6/$B6 -> 0.6735243
A15: 2020(p) | C15: =C7/$B7 -> 0.32626739 | D15: =D7/$B7 -> 0.67373261
A16: 2021(p) | C16: =C8/$B8 -> 0.32640338 | D16: =D8/$B8 -> 0.67359662
A17: 2022(p) | C17: =C9/$B9 -> 0.32843101 | D17: =D9/$B9 -> 0.67156899
A18: 2023(p) | C18: =C10/$B10 -> 0.33195851 | D18: =D10/$B10 -> 0.66804149
A21: AÑO | B21: T O T A L | C21: MACHOS | D21: HEMBRAS | F21: BOLIVIA: HATO BOVINO, EN MILLONES, AÑO 2016-2023
A22: 2016 | B22: =B3/1000000 -> 9.119344 | C22: 3097363 | D22: 6021981
A23: 2017 | B23: =B4/1000000 -> 9.304572 | C23: 3193636 | D23: 6110936
A24: 2018 | B24: =B5/1000000 -> 9.5561955 | C24: 3055342.6 | D24: 6500852.9
A25: 2019 | B25: =B6/1000000 -> 9.7414747 | C25: 3180354.7 | D25: 6561120
A26: 2020 (p) | B26: =B7/1000000 -> 10.103767 | C26: 3296529.7 | D26: 6807237.2
A27: 2021 (p) | B27: =B8/1000000 -> 10.385482 | C27: 3389856.4 | D27: 6995625.5
A28: 2022 (p) | B28: =B9/1000000 -> 10.739448 | C28: 3527167.9 | D28: 7212280.5
A29: 2023 (p) | B29: =B10/1000000 -> 11.099476 | C29: 3684565.6 | D29: 7414910.8

Sheet grafi 13
C1: 2016 | D1: 2017 | E1: 2018 | F1: 2019 | G1: 2020 | H1: 2021 | I1: 2022 (p) | J1: 2023 (p) | K1: 2024 (p)
B2: 3284.3001 | C2: 2615.8445 | D2: 2606.4294 | E2: 3244.3585 | F2: 5169.4045 | G2: 16666.211 | H2: 19142.386 | I2: 21249.387 | J2: 29301.808 | K2: 43439.011 | M2: =K2-J2 -> 14137.203
B4: Evolución de las exportaciones de carne bovina, en toneladas, período 2016 al mes de noviembre 2024

Sheet Grafi 14
C1: 2015 | D1: 2016 | E1: 2017 | F1: 2018 | G1: 2019 | H1: 2020 | I1: 2021 | J1: 2022 (p) | K1: 2023 | L1: 2024 (p) | M1: 2025 (p) | P1: 2016 | Q1: 2017 | R1: 2018 | S1: 2019 | T1: 2020 | U1: 2021 | V1: 2022 | W1: 2023 | X1: 2024 | Y1: 2024 (p)
B2: Carne bovina | C2: 3.2843001 | D2: 2.6158445 | E2: 2.6064294 | F2: 3.2443585 | G2: 5.1694045 | H2: 16.666211 | I2: 19.142386 | J2: 21.249387 | K2: 29.301808 | L2: =(Q6/1000)/1000 -> 46.892895 | M2: =(R6/1000)/1000 -> 43.882591 | O2: toneladas | P2: 3284.3001 | Q2: 2615.8445 | R2: 2606.4294 | S2: 3244.3585 | T2: 5169.4045 | U2: 16666.211 | V2: 19142.386 | W2: 21249.387 | X2: 29301.808 | Y2: 43439.011
B3: Variación (%) | D3: =(D2-C2)/C2 -> -0.2035306 | E3: =(E2-D2)/D2 -> -0.0035992659 | F3: =(F2-E2)/E2 -> 0.24475212 | G3: =(G2-F2)/F2 -> 0.59335181 | H3: =(H2-G2)/G2 -> 2.2240098 | I3: =(I2-H2)/H2 -> 0.14857461 | J3: =(J2-I2)/I2 -> 0.1100699 | K3: =(K2-J2)/J2 -> 0.37894839 | ... M3: =(M2-L2)/L2 -> -0.064195321 | O3: miles de tone | P3: =P2/1000 -> 3.2843001 | Q3: =Q2/1000 -> 2.6158445 | R3: =R2/1000 -> 2.6064294 | S3: =S2/1000 -> 3.2443585 | T3: =T2/1000 -> 5.1694045 | U3: =U2/1000 -> 16.666211 | V3: =V2/1000 -> 19.142386 | W3: =W2/1000 -> 21.249387 | ... Y3: =Y2/1000 -> 43.439011
B4: Absoluta | D4: =D2-C2 -> -0.66845558 | E4: =E2-D2 -> -0.00941512 | F4: =F2-E2 -> 0.63792911 | G4: =G2-F2 -> 1.925046 | H4: =H2-G2 -> 11.496806 | I4: =I2-H2 -> 2.4761757 | J4: =J2-I2 -> 2.1070005 | K4: =K2-J2 -> 8.0524211 | ... M4: =M2-L2 -> -3.0103045
D6: =AVERAGE(D3:G3) -> 0.15774351 | F6: =AVERAGE(H3:K3) -> 0.71540067 | Q6: 46892895 | R6: 43882591
B9: Bolivia: Evolución de las exportaciones de carne bovina, en toneladas, período 2016-2022 | I9: Bolivia:Crecimiento de las exportaciones de carne bovina, en miles de toneladas y porcentaje, período 2016-2022
B33: Mis colores:
B36: #388E3C | C36: #81C784 | D36: #1B5E20 | E36: #E8F5E9

Sheet Grafi 15
B1: 2016 | C1: 2017 | D1: 2018 | E1: 2019 | F1: 2020 | G1: 2021 | H1: 2022 (p) | I1: 2023 (p) | J1: 2024 (p)
A2: NANDINA | B2: Peso Bruto (Kg.) | C2: Peso Bruto (Kg.) | D2: Peso Bruto (Kg.) | E2: Peso Bruto (Kg.) | F2: Peso Bruto (Kg.) | G2: Peso Bruto (Kg.) | H2: Peso Bruto (Kg.) | I2: Peso Bruto (Kg.)
A3: 0201300000: CARNE DESHUESADA DE ANIMALES DE LA ESPECIE BOVINA, FRESCA O REFRIGERADA | B3: 784008.86 | C3: 664727.33 | D3: 821891.4 | E3: 519486.19 | F3: 721376.71 | G3: 675587.25 | H3: 0 | J3: 109819.09
A4: 0201300090: LAS DEMAS CARNE DE ANIMALES DE LA ESPECIE BOVINA, FRESCA O REFRIGERADA | B4: 0 | C4: 0 | D4: 0 | E4: 0 | F4: 0 | G4: 0 | H4: 72452.98 | I4: 131229.53 | J4: 1811788.9
A5: 0202300000: CARNE DESHUESADA DE ANIMALES DE LA ESPECIE BOVINA, CONGELADA | B5: 373258.94 | C5: 292400.12 | D5: 515681.49 | E5: 2551580.2 | F5: 14486519 | G5: 16802980 | H5: 70746.47
A6: 0202300010: CARNE DE ANIMALES DE LA ESPECIE BOVINA, CONGELADA: TRIMMING | B6: 0 | C6: 0 | D6: 0 | E6: 0 | F6: 0 | G6: 0 | H6: 2628275 | I6: 2041312.5
A7: 0202300090:LAS DEMAS CARNE DESHUESADA DE ANIMALES DE LA ESPECIE BOVINA, CONGELADA | B7: 0 | C7: 0 | D7: 0 | E7: 0 | F7: 0 | G7: 0 | H7: 16725757 | I7: 25074029
A8: 1602500000: LAS DEMAS PREPARACIONES Y CONSERVAS DE CARNE,DESPOJOS O SANGRE,DE LA ESPECIE BOVINA | B8: 1458576.7 | C8: 1649301.9 | D8: 1906785.6 | E8: 2098338.1 | F8: 1458315.5 | G8: 1663819.5 | H8: 1752155.6 | I8: 2055236.6
A10: FUENTE: Instituto Nacional de Estadística
B12: 2016 | C12: 2017 | D12: 2018 | E12: 2019 | F12: 2020 | G12: 2021 | H12: 2022 (p) | I12: 2023 (p) | J12: 2024 (p)
A13: Carne fresca o refrigera | B13: 784008.86 | C13: 664727.33 | D13: 821891.4 | E13: 519486.19 | F13: 721376.71 | G13: 675587.25 | H13: 72452.98 | I13: =+I4 -> 131229.53 | J13: =J3+J4 -> 1921607.9
A14: Carne congelada | B14: 373258.94 | C14: 292400.12 | D14: 515681.49 | E14: 2551580.2 | F14: 14486519 | G14: 16802980 | H14: 19424778 | I14: =+I6+I7 -> 27115342 | J14: 38764456
A15: Hamburguesa | B15: 1458576.7 | C15: 1649301.9 | D15: 1906785.6 | E15: 2098338.1 | F15: 1458315.5 | G15: 1663819.5 | H15: 1752155.6 | I15: =+I8 -> 2055236.6 | J15: 1811788.9
B16: =SUM(B13:B15) -> 2615844.5 | C16: =SUM(C13:C15) -> 2606429.4 | D16: =SUM(D13:D15) -> 3244358.5 | E16: =SUM(E13:E15) -> 5169404.5 | F16: =SUM(F13:F15) -> 16666211 | G16: =SUM(G13:G15) -> 19142386 | H16: =SUM(H13:H15) -> 21249387 | I16: =SUM(I13:I15) -> 29301808 | J16: =SUM(J13:J15) -> 42497853
B18: 2016 | C18: 2017 | D18: 2018 | E18: 2019 | F18: 2020 | G18: 2021 | H18: 2022 (p) | I18: 2023 (p) | J18: 2024 (p)
A19: Carne fresca o refrigera | B19: =B13/B$16 -> 0.29971539 | C19: =C13/C$16 -> 0.2550337 | D19: =D13/D$16 -> 0.2533294 | E19: =E13/E$16 -> 0.10049246 | F19: =F13/F$16 -> 0.043283787 | G19: =G13/G$16 -> 0.035292739 | H19: =H13/H$16 -> 0.0034096504 | I19: =I13/I$16 -> 0.0044785472 | J19: =J13/J$16 -> 0.045216589
A20: Carne congelada | B20: =B14/B$16 -> 0.14269156 | C20: =C14/C$16 -> 0.11218417 | D20: =D14/D$16 -> 0.15894713 | E20: =E14/E$16 -> 0.49359267 | F20: =F14/F$16 -> 0.86921489 | G20: =G14/G$16 -> 0.87778918 | H20: =H14/H$16 -> 0.91413359 | I20: =I14/I$16 -> 0.92538119 | J20: =J14/J$16 -> 0.91215093
A21: Hamburguesa | B21: =B15/B$16 -> 0.55759305 | C21: =C15/C$16 -> 0.63278213 | D21: =D15/D$16 -> 0.58772346 | E21: =E15/E$16 -> 0.40591487 | F21: =F15/F$16 -> 0.087501325 | G21: =G15/G$16 -> 0.086918082 | H21: =H15/H$16 -> 0.082456763 | I21: =I15/I$16 -> 0.070140267 | J21: =J15/J$16 -> 0.04263248
A22: TOTAL | B22: =B16/B$16 -> 1 | C22: =C16/C$16 -> 1 | D22: =D16/D$16 -> 1 | E22: =E16/E$16 -> 1 | F22: =F16/F$16 -> 1 | G22: =G16/G$16 -> 1 | H22: =H16/H$16 -> 1 | I22: =I16/I$16 -> 1 | J22: =J16/J$16 -> 1
A24: país | B24: 2016 | C24: 2017 | D24: 2018 | E24: 2019 | F24: 2020 | G24: 2021 | H24: 2022 (p) | I24: 2023 (p) | J24: 2024 (p)
A25: Carne congelada | B25: 0.14269156 | C25: 0.11218417 | D25: 0.15894713 | E25: 0.49359267 | F25: 0.86921489 | G25: 0.87778918 | H25: 0.91413359 | I25: 0.92538119 | J25: 0.92538119
A26: Hamburguesa | B26: 0.55759305 | C26: 0.63278213 | D26: 0.58772346 | E26: 0.40591487 | F26: 0.087501325 | G26: 0.086918082 | H26: 0.082456763 | I26: 0.070140267 | J26: 0.070140267
A27: Carne fresca o refrigera | B27: 0.29971539 | C27: 0.2550337 | D27: 0.2533294 | E27: 0.10049246 | F27: 0.043283787 | G27: 0.035292739 | H27: 0.0034096504 | I27: 0.0044785472 | J27: 0.0044785472

Sheet Graf 16
A2: Pequeña | B2: 0.4
A3: Mediano | B3: 0.3
A4: Grande | B4: 0.3
B5: =SUM(B2:B4) -> 1

Sheet Graf 17
A2: PAÍS | B2: 2016 | C2: 2017 | D2: 2018 | E2: 2019 | F2: 2020 | G2: 2021 | H2: 2022 | I2: 2023 | J2: TOTAL
A3: China | B3: 0 | C3: 0 | D3: 0 | E3: 2088327.1 | F3: 13995005 | G3: 16158396 | H3: 16575487 | I3: =SUM(B3:H3) -> 48817214 | J3: =SUM(B3:I3) -> 97634429 | K3: =J3/$J$16 -> 0.69054234
A4: Perú | B4: 1901646.2 | C4: 1744671.3 | D4: 2244260.1 | E4: 1967969.5 | F4: 1540449.5 | G4: 1536073.2 | H4: 1023468.7 | I4: =SUM(B4:H4) -> 11958538 | J4: =SUM(B4:I4) -> 23917077 | K4: =J4/$J$16 -> 0.16915912
A5: Ecuador | B5: 714198.35 | C5: 861758.13 | D5: 959990.85 | E5: 1053065.6 | F5: 860628.09 | G5: 1072983.2 | H5: 1037930.3 | I5: =SUM(B5:H5) -> 6560554.5 | J5: =SUM(B5:I5) -> 13121109 | K5: =J5/$J$16 -> 0.092802113
A6: Hong Kong | B6: 0 | C6: 0 | D6: 0 | E6: 0 | F6: 24431.43 | G6: 0 | H6: 2021040.3 | I6: =SUM(B6:H6) -> 2045471.7 | J6: =SUM(B6:I6) -> 4090943.4 | K6: =J6/$J$16 -> 0.028934154
A7: Federación de Rusia | B7: 0 | C7: 0 | D7: 0 | E7: 0 | F7: 0 | G7: 365645.7 | H7: 566774.65 | I7: =SUM(B7:H7) -> 932420.35 | J7: =SUM(B7:I7) -> 1864840.7 | K7: =J7/$J$16 -> 0.013189522 | O7: 2016 | P7: 2017 | Q7: 2018 | R7: 2019 | S7: 2020 | T7: 2021 | U7: 2022 | V7: 2023
A8: República del Congo | B8: 0 | C8: 0 | D8: 0 | E8: 0 | F8: 171636.8 | G8: 7096.26 | H8: 0 | I8: =SUM(B8:H8) -> 178733.06 | J8: =SUM(B8:I8) -> 357466.12 | K8: =J8/$J$16 -> 0.0025282628 | O8: 2615844.5 | P8: 2606429.4 | Q8: 3244358.5 | R8: 5169404.5 | S8: 16666211 | T8: 19142386 | U8: 21249387 | V8: 70694021
A9: Vietnam | B9: 0 | C9: 0 | D9: 39040.63 | E9: 59462.33 | F9: 72956.38 | G9: 0 | H9: 0 | I9: =SUM(B9:H9) -> 171459.34 | J9: =SUM(B9:I9) -> 342918.68 | K9: =J9/$J$16 -> 0.0024253726
A10: Angola | B10: 0 | C10: 0 | D10: 0 | E10: 0 | F10: 0 | G10: 0 | H10: 24425.81 | I10: =SUM(B10:H10) -> 24425.81 | J10: =SUM(B10:I10) -> 48851.62 | K10: =J10/$J$16 -> 0.00034551451 | O10: AÑO | P10: VOLUMEN
A11: Gabón | B11: 0 | C11: 0 | D11: 0 | E11: 0 | F11: 1104 | G11: 2192.53 | H11: 0 | I11: =SUM(B11:H11) -> 3296.53 | J11: =SUM(B11:I11) -> 6593.06 | O11: 2016 | P11: 2615844.5
A12: Colombia | B12: 0 | C12: 0 | D12: 1025.5 | E12: 0 | F12: 0 | G12: 0 | H12: 0 | I12: =SUM(B12:H12) -> 1025.5 | J12: =SUM(B12:I12) -> 2051 | O12: 2017 | P12: 2606429.4
A13: Francia | B13: 0 | C13: 0 | D13: 0 | E13: 580 | F13: 0 | G13: 0 | H13: 0 | I13: =SUM(B13:H13) -> 580 | J13: =SUM(B13:I13) -> 1160 | O13: 2018 | P13: 3244358.5
A14: Malasia | B14: 0 | C14: 0 | D14: 0 | E14: 0 | F14: 0 | G14: 0 | H14: 259.85 | I14: =SUM(B14:H14) -> 259.85 | J14: =SUM(B14:I14) -> 519.7 | O14: 2019 | P14: 5169404.5
A15: Brasil | B15: 0 | C15: 0 | D15: 41.45 | E15: 0 | F15: 0 | G15: 0 | H15: 0 | I15: =SUM(B15:H15) -> 41.45 | J15: =SUM(B15:I15) -> 82.9 | O15: 2020 | P15: 16666211
B16: =SUM(B3:B15) -> 2615844.5 | C16: =SUM(C3:C15) -> 2606429.4 | D16: =SUM(D3:D15) -> 3244358.5 | E16: =SUM(E3:E15) -> 5169404.5 | F16: =SUM(F3:F15) -> 16666211 | G16: =SUM(G3:G15) -> 19142386 | H16: =SUM(H3:H15) -> 21249387 | I16: =SUM(I3:I15) -> 70694021 | J16: =SUM(J3:J15) -> 1.4138804e+08 | O16: 2021 | P16: 19142386
O17: 2022 | P17: 21249387
O18: 2023 | P18: 70694021
E20: Principales países de destino de las exportaciones de carne bovina, en % sobre el volumen, período 2016-2023
F41: PAÍS | G41: TOTAL | H41: %
F42: China | G42: 97634429 | H42: =G42/$G$55 -> 0.69054234
F43: Perú | G43: 23917077 | H43: =G43/$G$55 -> 0.16915912
F44: Ecuador | G44: 13121109 | H44: =G44/$G$55 -> 0.092802113
F45: Hong Kong | G45: 4090943.4 | H45: =G45/$G$55 -> 0.028934154
F46: Federación de Rusia | G46: 1864840.7 | H46: =G46/$G$55 -> 0.013189522
F47: República del Congo | G47: 357466.12 | H47: =G47/$G$55 -> 0.0025282628
F48: Vietnam | G48: 342918.68 | H48: =G48/$G$55 -> 0.0024253726
F49: Angola | G49: 48851.62 | H49: =G49/$G$55 -> 0.00034551451
F50: Gabón | G50: 6593.06 | H50: =G50/$G$55 -> 4.6630959e-05
F51: Colombia | G51: 2051 | H51: =G51/$G$55 -> 1.4506177e-05
F52: Francia | G52: 1160 | H52: =G52/$G$55 -> 8.2043713e-06
F53: Malasia | G53: 519.7 | H53: =G53/$G$55 -> 3.6756998e-06
F54: Brasil | G54: 82.9 | H54: =G54/$G$55 -> 5.8632964e-07
G55: =SUM(G42:G54) -> 1.4138804e+08

Sheet Tabla 1
B1: Datos
A2: Country Name | B2: Suma de 2016 | C2: Suma de 2017 | D2: Suma de 2018 | E2: Suma de 2019 | F2: Suma de 2020 | G2: Suma de 2021 | H2: Suma de 2022 | I2: Suma de 2023
A3: China | B3: 1.1819153e+13 | C3: 1.2640254e+13 | D3: 1.3493442e+13 | E3: 1.429637e+13 | F3: 1.4616414e+13 | G3: 1.5851277e+13 | H3: 1.6325085e+13 | I3: 1.7173989e+13
A4: Perú | B4: 1.9730649e+11 | C4: 2.0227632e+11 | D4: 2.1030538e+11 | E4: 2.1501755e+11 | F4: 1.9150902e+11 | G4: 2.1708549e+11 | H4: 2.2300215e+11 | I4: 2.2177523e+11
A5: Ecuador | B5: 9.6540801e+10 | C5: 1.0230467e+11 | D5: 1.0337303e+11 | E5: 1.0354402e+11 | F5: 9.3971273e+10 | G5: 1.0319777e+11 | H5: 1.0958172e+11 | I5: 1.1216261e+11
A6: Total general | B6: 1.2113001e+13 | C6: 1.2944835e+13 | D6: 1.3807121e+13 | E6: 1.4614931e+13 | F6: 1.4901894e+13 | G6: 1.617156e+13 | H6: 1.6657669e+13 | I6: 1.7507927e+13
B8: Países seleccionados: Producto Interno Bruto a precios constantes de 2015 de dólares.
B9: Período 2016-2023
B10: PIB (US$ a precios constantes de 2015, en millones de dólares)
B13: PAÍSES | C13: China | D13: Perú | E13: Ecuador
B14: 2015
B15: 2016 | C15: 11819153 | D15: 197306.49 | E15: 96540.801
B16: 2017 | C16: 12640254 | D16: 202276.32 | E16: 102304.67
B17: 2018 | C17: 13493442 | D17: 210305.38 | E17: 103373.03
B18: 2019 | C18: 14296370 | D18: 215017.55 | E18: 103544.02
B19: 2020 | C19: 14616414 | D19: 191509.02 | E19: 93971.273
B20: 2021 (p) | C20: 15851277 | D20: 217085.49 | E20: 103197.77
B21: 2022 (p) | C21: 16325085 | D21: 223002.15 | E21: 109581.72
B22: 2023 (p) | C22: 17173989 | D22: 221775.23 | E22: 112162.61
B25: 2017 | C25: =(C16-C15)/C15 -> 0.069472008 | D25: =(D16-D15)/D15 -> 0.025188354 | E25: =(E16-E15)/E15 -> 0.059703988
B26: 2018 | C26: =(C17-C16)/C16 -> 0.067497738 | D26: =(D17-D16)/D16 -> 0.039693513 | E26: =(E17-E16)/E16 -> 0.010442955
B27: 2019 | C27: =(C18-C17)/C17 -> 0.059505008 | D27: =(D18-D17)/D17 -> 0.022406318 | E27: =(E18-E17)/E17 -> 0.0016540353
B28: 2020 | C28: =(C19-C18)/C18 -> 0.022386384 | D28: =(D19-D18)/D18 -> -0.10933307 | E28: =(E19-E18)/E18 -> -0.092450964
B29: 2021 (p) | C29: =(C20-C19)/C19 -> 0.084484694 | D29: =(D20-D19)/D19 -> 0.1335523 | E29: =(E20-E19)/E19 -> 0.098184177
B30: 2022 (p) | C30: =(C21-C20)/C20 -> 0.029890841 | D30: =(D21-D20)/D20 -> 0.027255002 | E30: =(E21-E20)/E20 -> 0.061861391
B31: 2023 (p) | C31: =(C22-C21)/C21 -> 0.052 | D31: =(D22-D21)/D21 -> -0.0055018231 | E31: =(E22-E21)/E21 -> 0.023552179
C32: =AVERAGE(C28:C31) -> 0.04719048 | D32: =AVERAGE(D25:D31) -> 0.019037228 | E32: =AVERAGE(E25:E31) -> 0.023278252

Sheet Tab 2
B1: Bolivia: Tipo de cambio real multilateral, período 2016-2023,
B2: base (agosto de 2003 = 100)
B3: AÑO | C3: TCRM
B4: 2016 | C4: 62.7
B5: 2017 | C5: 64.1
B6: 2018 | C6: 62.4
B7: 2019 | C7: 60.2
B8: 2020 | C8: 57.8
B9: 2021 | C9: 59.6
B10: 2022 | C10: 59.5
B11: 2023 | C11: 61.5

Sheet Tab 3
B2: Evolución del Índice en Términos de Intercambio, período 2016-2023
B4: AÑO | C4: ITI
B5: 2016 | C5: 100.01237
B6: 2017 | C6: 114.79607
B7: 2018 | C7: 114.9559
B8: 2019 | C8: 107.77403
B9: 2020 | C9: 92.471913
B10: 2021 | C10: 101.37914
B11: 2022 (p) | C11: 95.958904
B12: 2023 (p) | C12: 95.252194
